#VRML_SIM R2023b utf8

EXTERNPROTO "https://raw.githubusercontent.com/cyberbotics/webots/R2023b/projects/appearances/protos/OsbWood.proto"
EXTERNPROTO "https://raw.githubusercontent.com/cyberbotics/webots/R2023b/projects/objects/floors/protos/RectangleArena.proto"
EXTERNPROTO "https://raw.githubusercontent.com/cyberbotics/webots/R2023b/projects/objects/backgrounds/protos/TexturedBackground.proto"
EXTERNPROTO "https://raw.githubusercontent.com/cyberbotics/webots/R2023b/projects/objects/backgrounds/protos/TexturedBackgroundLight.proto"

WorldInfo {
  info [
    "In this example, the robot moves down a slope."
    "The altimeter is used to record the robots height."
  ]
  title "Altimeter"
  basicTimeStep 8
  contactProperties [
    ContactProperties {
      material2 "body"
      coulombFriction [
        0
      ]
      softCFM 0.1
    }
  ]
}
Viewpoint {
  orientation -0.14988547262953592 -0.9704918320047565 -0.18889136853406532 5.919376509294902
  position -1.580945133923684 -0.15163314536096006 0.9324348578542014
}
TexturedBackground {
}
TexturedBackgroundLight {
}
RectangleArena {
}
PointLight {
  attenuation 0 0 1
  intensity 0.6
  location 0.6 0 0
}
DEF SLOPE Solid {
  translation 0 0 0.15
  rotation 0 1 0 -0.4
  children [
    Shape {
      appearance OsbWood {
        textureTransform TextureTransform {
          scale 0.5 2
        }
      }
      geometry DEF BOX0 Box {
        size 0.8 0.2 0.02
      }
    }
  ]
  name "green box"
  boundingObject USE BOX0
}
Robot {
  translation -0.1014314600477188 1.7104641850157527e-05 0.11807777430300079
  rotation -0.24583003729173372 -1.1647763791173382e-06 0.9693129488270483 3.14154886431188
  children [
    Altimeter {
    }
    Pose {
      translation 0 0 0.0415
      children [
        Shape {
          appearance PBRAppearance {
            baseColor 0.0820075 0.364731 0.8
            roughness 1
            metalness 0
          }
          geometry DEF BODY Cylinder {
            height 0.08
            radius 0.045
          }
        }
      ]
    }
    HingeJoint {
      jointParameters HingeJointParameters {
        position 16.720002474304877
        axis 0 1 0
        anchor 0 0 0.025
      }
      device [
        RotationalMotor {
          name "left wheel motor"
          consumptionFactor 70
        }
        PositionSensor {
          name "left wheel sensor"
        }
      ]
      endPoint Solid {
        translation 0 0.04499999999999979 0.025
        rotation -0.6929920039846805 0.6929920567049115 -0.19880666929756952 2.7490969825875524
        children [
          DEF WHEEL Pose {
            rotation 0.577656895078166 0.5771968951617173 -0.5771968951617173 -2.093935
            children [
              Shape {
                appearance PBRAppearance {
                  baseColor 1 0 0
                  roughness 1
                  metalness 0
                }
                geometry Cylinder {
                  height 0.01
                  radius 0.025
                }
              }
            ]
          }
        ]
        name "left wheel"
        boundingObject USE WHEEL
        physics DEF PHYSICS_WHEEL Physics {
          density -1
          mass 0.05
        }
        linearVelocity -5.279189249094369e-06 -2.0780724968879072e-13 -2.2320009656691924e-06
        angularVelocity 9.433603624016635e-09 -1.0290490342464004e-08 -2.2286119926094457e-08
      }
    }
    HingeJoint {
      jointParameters HingeJointParameters {
        position 16.720002463809884
        axis 0 1 0
        anchor 0 0 0.025
      }
      device [
        RotationalMotor {
          name "right wheel motor"
          consumptionFactor 70
        }
        PositionSensor {
          name "right wheel sensor"
        }
      ]
      endPoint Solid {
        translation 0 -0.04499999999999996 0.025
        rotation -0.692992003442445 0.6929920561626768 -0.19880667307777114 2.749096975314605
        children [
          USE WHEEL
        ]
        boundingObject USE WHEEL
        physics USE PHYSICS_WHEEL
        linearVelocity -5.277183505136242e-06 -3.078016130300408e-13 -2.231151922770268e-06
        angularVelocity 9.433621031453497e-09 -1.0290547618367743e-08 -2.2286125053574862e-08
      }
    }
    DistanceSensor {
      translation 0.042 0.02 0.062
      rotation 0 0 -1 -0.5
      children [
        DEF SENSOR Transform {
          rotation 0.5773502691896258 0.5773502691896258 -0.5773502691896258 -2.1
          children [
            Shape {
              appearance PBRAppearance {
                baseColor 1 1 0.290196
                roughness 1
                metalness 0
              }
              geometry Cylinder {
                height 0.004
                radius 0.008
              }
            }
          ]
        }
      ]
      name "ds0"
      lookupTable [
        0 1024 0
        0.05 1024 0
        0.15 0 0
      ]
      numberOfRays 2
      aperture 1
    }
    DistanceSensor {
      translation 0.042 -0.02 0.062
      rotation 0 0 1 -0.5
      children [
        DEF SENSOR Transform {
          rotation 0.5773502691896258 0.5773502691896258 -0.5773502691896258 -2.1
          children [
            Shape {
              appearance PBRAppearance {
                baseColor 1 1 0.290196
                roughness 1
                metalness 0
              }
              geometry Cylinder {
                height 0.004
                radius 0.008
              }
            }
          ]
        }
      ]
      name "ds1"
      lookupTable [
        0 1024 0
        0.05 1024 0
        0.15 0 0
      ]
      numberOfRays 2
      aperture 1
    }
    DEF SMILE Transform {
      translation 0.036 0 0.025
      rotation 0.23570226039551587 -0.9428090415820635 -0.23570226039551587 1.6
      children [
        Shape {
          appearance PBRAppearance {
            baseColor 0.941176 0.145098 1
            roughness 1
            metalness 0
          }
          geometry Cylinder {
            height 0.018
            radius 0.009
            subdivision 3
          }
        }
      ]
    }
  ]
  name "MyBot"
  contactMaterial "body"
  boundingObject Pose {
    translation 0 0 0.0415
    rotation 0 0 1 -1.570796
    children [
      USE BODY
    ]
  }
  physics Physics {
    density -1
    mass 0.5
  }
  controller ""
  linearVelocity -5.2783357113293065e-06 3.8146501567600203e-11 -2.231657289911771e-06
  angularVelocity 9.433606993282042e-09 -1.0290487244720338e-08 -2.2286118244284338e-08
}
